<?xml version="1.0"?>
<robot name="roomba">
  <!-- Fixed joint connecting map to odom (normally published by SLAM or localization node) -->
  <!-- These are just for visualization in RViz without SLAM running -->
  
  <!-- Base link -->
  <link name="base_link">
    <visual>
      <geometry>
        <cylinder length="0.04" radius="0.17425"/>
      </geometry>
      <material name="white">
        <color rgba="1 1 1 1"/>
      </material>
    </visual>
    <collision>
      <geometry>
        <cylinder length="0.04" radius="0.17425"/>
      </geometry>
    </collision>
    <inertial>
      <mass value="2.0"/>
      <inertia ixx="0.01" ixy="0.0" ixz="0.0" iyy="0.01" iyz="0.0" izz="0.02"/>
    </inertial>
  </link>

  <!-- Wheel links -->
  <link name="left_wheel">
    <visual>
      <geometry>
        <cylinder length="0.02" radius="0.03"/>
      </geometry>
      <material name="black">
        <color rgba="0 0 0 1"/>
      </material>
    </visual>
    <collision>
      <geometry>
        <cylinder length="0.02" radius="0.03"/>
      </geometry>
    </collision>
    <inertial>
      <mass value="0.1"/>
      <inertia ixx="0.0001" ixy="0.0" ixz="0.0" iyy="0.0001" iyz="0.0" izz="0.0002"/>
    </inertial>
  </link>

  <link name="right_wheel">
    <visual>
      <geometry>
        <cylinder length="0.02" radius="0.03"/>
      </geometry>
      <material name="black">
        <color rgba="0 0 0 1"/>
      </material>
    </visual>
    <collision>
      <geometry>
        <cylinder length="0.02" radius="0.03"/>
      </geometry>
    </collision>
    <inertial>
      <mass value="0.1"/>
      <inertia ixx="0.0001" ixy="0.0" ixz="0.0" iyy="0.0001" iyz="0.0" izz="0.0002"/>
    </inertial>
  </link>

  <!-- Caster wheel -->
  <link name="caster_wheel">
    <visual>
      <geometry>
        <sphere radius="0.02"/>
      </geometry>
      <material name="black"/>
    </visual>
    <collision>
      <geometry>
        <sphere radius="0.02"/>
      </geometry>
    </collision>
    <inertial>
      <mass value="0.05"/>
      <inertia ixx="0.0001" ixy="0.0" ixz="0.0" iyy="0.0001" iyz="0.0" izz="0.0001"/>
    </inertial>
  </link>

  <!-- Joints -->
  <joint name="left_wheel_joint" type="continuous">
    <parent link="base_link"/>
    <child link="left_wheel"/>
    <origin xyz="0 0.1175 -0.01" rpy="1.5708 0 0"/>
    <axis xyz="0 0 1"/>
  </joint>

  <joint name="right_wheel_joint" type="continuous">
    <parent link="base_link"/>
    <child link="right_wheel"/>
    <origin xyz="0 -0.1175 -0.01" rpy="1.5708 0 0"/>
    <axis xyz="0 0 1"/>
  </joint>

  <joint name="caster_wheel_joint" type="fixed">
    <parent link="base_link"/>
    <child link="caster_wheel"/>
    <origin xyz="-0.15425 0 -0.04"/>
  </joint>

  <!-- ROS2 Control -->
  <ros2_control name="RoombaSystem" type="system">
    <hardware>
      <plugin>mock_components/GenericSystem</plugin>
    </hardware>
    <joint name="left_wheel_joint">
      <command_interface name="velocity"/>
      <state_interface name="position"/>
      <state_interface name="velocity"/>
    </joint>
    <joint name="right_wheel_joint">
      <command_interface name="velocity"/>
      <state_interface name="position"/>
      <state_interface name="velocity"/>
    </joint>
  </ros2_control>

  <gazebo>
    <plugin name="roomba_control" filename="libgazebo_ros2_control.so">
      <parameters>/home/panda/study/ros/roomba/roomba_ws/src/roomba_bringup/config/roomba_controllers.yaml</parameters>
    </plugin>
  </gazebo>
</robot>